[2025-02-18T07:05:22.321+0000] {local_task_job_runner.py:123} INFO - ::group::Pre task execution logs
[2025-02-18T07:05:22.342+0000] {taskinstance.py:2613} INFO - Dependencies all met for dep_context=non-requeueable deps ti=<TaskInstance: fetch_cryptocurrencies_data.insert_coin_data_postgres manual__2025-02-18T06:59:59.702060+00:00 [queued]>
[2025-02-18T07:05:22.352+0000] {taskinstance.py:2613} INFO - Dependencies all met for dep_context=requeueable deps ti=<TaskInstance: fetch_cryptocurrencies_data.insert_coin_data_postgres manual__2025-02-18T06:59:59.702060+00:00 [queued]>
[2025-02-18T07:05:22.354+0000] {taskinstance.py:2866} INFO - Starting attempt 2 of 2
[2025-02-18T07:05:22.373+0000] {taskinstance.py:2889} INFO - Executing <Task(PythonOperator): insert_coin_data_postgres> on 2025-02-18 06:59:59.702060+00:00
[2025-02-18T07:05:22.381+0000] {warnings.py:112} WARNING - /home/***/.local/lib/python3.12/site-packages/***/task/task_runner/standard_task_runner.py:70: DeprecationWarning: This process (pid=305) is multi-threaded, use of fork() may lead to deadlocks in the child.
  pid = os.fork()

[2025-02-18T07:05:22.383+0000] {standard_task_runner.py:104} INFO - Running: ['***', 'tasks', 'run', 'fetch_cryptocurrencies_data', 'insert_coin_data_postgres', 'manual__2025-02-18T06:59:59.702060+00:00', '--job-id', '99', '--raw', '--subdir', 'DAGS_FOLDER/crypto_coins_dag.py', '--cfg-path', '/tmp/tmp15dlwm7e']
[2025-02-18T07:05:22.384+0000] {standard_task_runner.py:72} INFO - Started process 307 to run task
[2025-02-18T07:05:22.384+0000] {standard_task_runner.py:105} INFO - Job 99: Subtask insert_coin_data_postgres
[2025-02-18T07:05:22.444+0000] {task_command.py:467} INFO - Running <TaskInstance: fetch_cryptocurrencies_data.insert_coin_data_postgres manual__2025-02-18T06:59:59.702060+00:00 [running]> on host df376234e961
[2025-02-18T07:05:22.552+0000] {taskinstance.py:3132} INFO - Exporting env vars: AIRFLOW_CTX_DAG_EMAIL='olalekanrasaq1331@gmail.com' AIRFLOW_CTX_DAG_OWNER='Akinkunmi' AIRFLOW_CTX_DAG_ID='fetch_cryptocurrencies_data' AIRFLOW_CTX_TASK_ID='insert_coin_data_postgres' AIRFLOW_CTX_EXECUTION_DATE='2025-02-18T06:59:59.702060+00:00' AIRFLOW_CTX_TRY_NUMBER='2' AIRFLOW_CTX_DAG_RUN_ID='manual__2025-02-18T06:59:59.702060+00:00'
[2025-02-18T07:05:22.554+0000] {logging_mixin.py:190} INFO - Task instance is in running state
[2025-02-18T07:05:22.554+0000] {logging_mixin.py:190} INFO -  Previous state of the Task instance: queued
[2025-02-18T07:05:22.555+0000] {logging_mixin.py:190} INFO - Current task name:insert_coin_data_postgres state:running start_date:2025-02-18 07:05:22.343055+00:00
[2025-02-18T07:05:22.555+0000] {logging_mixin.py:190} INFO - Dag name:fetch_cryptocurrencies_data and current dag run status:running
[2025-02-18T07:05:22.556+0000] {taskinstance.py:731} INFO - ::endgroup::
[2025-02-18T07:05:22.581+0000] {base.py:84} INFO - Retrieving connection 'Cryptocurrencies_connection'
[2025-02-18T07:05:22.585+0000] {sql.py:553} INFO - Running statement: 
    INSERT INTO coins_data (id, name, symbol, price, percent_change_24h, percent_change_7d, percent_change_30d, market_cap, circulating_supply)
    VALUES (%s, %s, %s, %s, %s, %s, %s, %s, %s)
    , parameters: (1, 'Bitcoin', 'BTC', 95316.6, -1.09, -3.18, -9.59, 1889734914654.63, 19825875.0)
[2025-02-18T07:05:22.587+0000] {taskinstance.py:3311} ERROR - Task failed with exception
Traceback (most recent call last):
  File "/home/airflow/.local/lib/python3.12/site-packages/airflow/models/taskinstance.py", line 767, in _execute_task
    result = _execute_callable(context=context, **execute_callable_kwargs)
             ^^^^^^^^^^^^^^^^^^^^^^^^^^^^^^^^^^^^^^^^^^^^^^^^^^^^^^^^^^^^^
  File "/home/airflow/.local/lib/python3.12/site-packages/airflow/models/taskinstance.py", line 733, in _execute_callable
    return ExecutionCallableRunner(
           ^^^^^^^^^^^^^^^^^^^^^^^^
  File "/home/airflow/.local/lib/python3.12/site-packages/airflow/utils/operator_helpers.py", line 252, in run
    return self.func(*args, **kwargs)
           ^^^^^^^^^^^^^^^^^^^^^^^^^^
  File "/home/airflow/.local/lib/python3.12/site-packages/airflow/models/baseoperator.py", line 422, in wrapper
    return func(self, *args, **kwargs)
           ^^^^^^^^^^^^^^^^^^^^^^^^^^^
  File "/home/airflow/.local/lib/python3.12/site-packages/airflow/operators/python.py", line 238, in execute
    return_value = self.execute_callable()
                   ^^^^^^^^^^^^^^^^^^^^^^^
  File "/home/airflow/.local/lib/python3.12/site-packages/airflow/operators/python.py", line 256, in execute_callable
    return runner.run(*self.op_args, **self.op_kwargs)
           ^^^^^^^^^^^^^^^^^^^^^^^^^^^^^^^^^^^^^^^^^^^
  File "/home/airflow/.local/lib/python3.12/site-packages/airflow/utils/operator_helpers.py", line 252, in run
    return self.func(*args, **kwargs)
           ^^^^^^^^^^^^^^^^^^^^^^^^^^
  File "/opt/airflow/dags/crypto_coins_dag.py", line 67, in insert_data_into_postgres
    postgres_hook.run(insert_query, parameters=(coin["id"], coin["Name"], coin["Symbol"], coin["Price"], coin["24h Percent Change"], coin["7d Percent Change"], coin["30d Percent Change"], coin["Market Cap"], coin["Circulating Supply"]))
  File "/home/airflow/.local/lib/python3.12/site-packages/airflow/providers/common/sql/hooks/sql.py", line 498, in run
    self._run_command(cur, sql_statement, parameters)
  File "/home/airflow/.local/lib/python3.12/site-packages/airflow/providers/common/sql/hooks/sql.py", line 556, in _run_command
    cur.execute(sql_statement, parameters)
psycopg2.errors.UniqueViolation: duplicate key value violates unique constraint "coins_data_pkey"
DETAIL:  Key (id)=(1) already exists.

[2025-02-18T07:05:22.607+0000] {logging_mixin.py:190} INFO - Task instance in failure state
[2025-02-18T07:05:22.609+0000] {logging_mixin.py:190} INFO - Task start:2025-02-18 07:05:22.343055+00:00 end:2025-02-18 07:05:22.607143+00:00 duration:0.264088
[2025-02-18T07:05:22.610+0000] {logging_mixin.py:190} INFO - Task:<Task(PythonOperator): insert_coin_data_postgres> dag:<DAG: fetch_cryptocurrencies_data> dagrun:<DagRun fetch_cryptocurrencies_data @ 2025-02-18 06:59:59.702060+00:00: manual__2025-02-18T06:59:59.702060+00:00, state:running, queued_at: 2025-02-18 06:59:59.718188+00:00. externally triggered: True>
[2025-02-18T07:05:22.610+0000] {logging_mixin.py:190} INFO - Failure caused by duplicate key value violates unique constraint "coins_data_pkey"
DETAIL:  Key (id)=(1) already exists.
[2025-02-18T07:05:22.611+0000] {taskinstance.py:1225} INFO - Marking task as FAILED. dag_id=fetch_cryptocurrencies_data, task_id=insert_coin_data_postgres, run_id=manual__2025-02-18T06:59:59.702060+00:00, execution_date=20250218T065959, start_date=20250218T070522, end_date=20250218T070522
[2025-02-18T07:05:22.630+0000] {warnings.py:112} WARNING - /home/***/.local/lib/python3.12/site-packages/***/utils/email.py:155: RemovedInAirflow3Warning: Fetching SMTP credentials from configuration variables will be deprecated in a future release. Please set credentials using a connection instead.
  send_mime_email(e_from=mail_from, e_to=recipients, mime_msg=msg, conn_id=conn_id, dryrun=dryrun)

[2025-02-18T07:05:22.632+0000] {configuration.py:1074} WARNING - section/key [smtp/smtp_user] not found in config
[2025-02-18T07:05:22.633+0000] {email.py:272} INFO - Email alerting: attempt 1
[2025-02-18T07:05:22.642+0000] {configuration.py:1074} WARNING - section/key [smtp/smtp_user] not found in config
[2025-02-18T07:05:22.643+0000] {email.py:272} INFO - Email alerting: attempt 1
[2025-02-18T07:05:22.644+0000] {taskinstance.py:1234} ERROR - Failed to send email to: ['olalekanrasaq1331@gmail.com']
Traceback (most recent call last):
  File "/home/airflow/.local/lib/python3.12/site-packages/airflow/models/taskinstance.py", line 273, in _run_raw_task
    TaskInstance._execute_task_with_callbacks(
  File "/home/airflow/.local/lib/python3.12/site-packages/airflow/models/taskinstance.py", line 3159, in _execute_task_with_callbacks
    result = self._execute_task(context, task_orig)
             ^^^^^^^^^^^^^^^^^^^^^^^^^^^^^^^^^^^^^^
  File "/home/airflow/.local/lib/python3.12/site-packages/airflow/models/taskinstance.py", line 3183, in _execute_task
    return _execute_task(self, context, task_orig)
           ^^^^^^^^^^^^^^^^^^^^^^^^^^^^^^^^^^^^^^^
  File "/home/airflow/.local/lib/python3.12/site-packages/airflow/models/taskinstance.py", line 767, in _execute_task
    result = _execute_callable(context=context, **execute_callable_kwargs)
             ^^^^^^^^^^^^^^^^^^^^^^^^^^^^^^^^^^^^^^^^^^^^^^^^^^^^^^^^^^^^^
  File "/home/airflow/.local/lib/python3.12/site-packages/airflow/models/taskinstance.py", line 733, in _execute_callable
    return ExecutionCallableRunner(
           ^^^^^^^^^^^^^^^^^^^^^^^^
  File "/home/airflow/.local/lib/python3.12/site-packages/airflow/utils/operator_helpers.py", line 252, in run
    return self.func(*args, **kwargs)
           ^^^^^^^^^^^^^^^^^^^^^^^^^^
  File "/home/airflow/.local/lib/python3.12/site-packages/airflow/models/baseoperator.py", line 422, in wrapper
    return func(self, *args, **kwargs)
           ^^^^^^^^^^^^^^^^^^^^^^^^^^^
  File "/home/airflow/.local/lib/python3.12/site-packages/airflow/operators/python.py", line 238, in execute
    return_value = self.execute_callable()
                   ^^^^^^^^^^^^^^^^^^^^^^^
  File "/home/airflow/.local/lib/python3.12/site-packages/airflow/operators/python.py", line 256, in execute_callable
    return runner.run(*self.op_args, **self.op_kwargs)
           ^^^^^^^^^^^^^^^^^^^^^^^^^^^^^^^^^^^^^^^^^^^
  File "/home/airflow/.local/lib/python3.12/site-packages/airflow/utils/operator_helpers.py", line 252, in run
    return self.func(*args, **kwargs)
           ^^^^^^^^^^^^^^^^^^^^^^^^^^
  File "/opt/airflow/dags/crypto_coins_dag.py", line 67, in insert_data_into_postgres
    postgres_hook.run(insert_query, parameters=(coin["id"], coin["Name"], coin["Symbol"], coin["Price"], coin["24h Percent Change"], coin["7d Percent Change"], coin["30d Percent Change"], coin["Market Cap"], coin["Circulating Supply"]))
  File "/home/airflow/.local/lib/python3.12/site-packages/airflow/providers/common/sql/hooks/sql.py", line 498, in run
    self._run_command(cur, sql_statement, parameters)
  File "/home/airflow/.local/lib/python3.12/site-packages/airflow/providers/common/sql/hooks/sql.py", line 556, in _run_command
    cur.execute(sql_statement, parameters)
psycopg2.errors.UniqueViolation: duplicate key value violates unique constraint "coins_data_pkey"
DETAIL:  Key (id)=(1) already exists.


During handling of the above exception, another exception occurred:

Traceback (most recent call last):
  File "/home/airflow/.local/lib/python3.12/site-packages/airflow/models/taskinstance.py", line 1442, in _email_alert
    send_email(task.email, subject, html_content)
  File "/home/airflow/.local/lib/python3.12/site-packages/airflow/utils/email.py", line 80, in send_email
    return backend(
           ^^^^^^^^
  File "/home/airflow/.local/lib/python3.12/site-packages/airflow/utils/email.py", line 155, in send_email_smtp
    send_mime_email(e_from=mail_from, e_to=recipients, mime_msg=msg, conn_id=conn_id, dryrun=dryrun)
  File "/home/airflow/.local/lib/python3.12/site-packages/airflow/utils/email.py", line 274, in send_mime_email
    smtp_conn = _get_smtp_connection(smtp_host, smtp_port, smtp_timeout, smtp_ssl)
                ^^^^^^^^^^^^^^^^^^^^^^^^^^^^^^^^^^^^^^^^^^^^^^^^^^^^^^^^^^^^^^^^^^
  File "/home/airflow/.local/lib/python3.12/site-packages/airflow/utils/email.py", line 318, in _get_smtp_connection
    return smtplib.SMTP(host=host, port=port, timeout=timeout)
           ^^^^^^^^^^^^^^^^^^^^^^^^^^^^^^^^^^^^^^^^^^^^^^^^^^^
  File "/usr/local/lib/python3.12/smtplib.py", line 255, in __init__
    (code, msg) = self.connect(host, port)
                  ^^^^^^^^^^^^^^^^^^^^^^^^
  File "/usr/local/lib/python3.12/smtplib.py", line 341, in connect
    self.sock = self._get_socket(host, port, self.timeout)
                ^^^^^^^^^^^^^^^^^^^^^^^^^^^^^^^^^^^^^^^^^^
  File "/usr/local/lib/python3.12/smtplib.py", line 312, in _get_socket
    return socket.create_connection((host, port), timeout,
           ^^^^^^^^^^^^^^^^^^^^^^^^^^^^^^^^^^^^^^^^^^^^^^^
  File "/usr/local/lib/python3.12/socket.py", line 865, in create_connection
    raise exceptions[0]
  File "/usr/local/lib/python3.12/socket.py", line 850, in create_connection
    sock.connect(sa)
ConnectionRefusedError: [Errno 111] Connection refused

During handling of the above exception, another exception occurred:

Traceback (most recent call last):
  File "/home/airflow/.local/lib/python3.12/site-packages/airflow/models/taskinstance.py", line 1232, in _handle_failure
    task_instance.email_alert(error, failure_context["task"])
  File "/home/airflow/.local/lib/python3.12/site-packages/airflow/models/taskinstance.py", line 3605, in email_alert
    _email_alert(task_instance=self, exception=exception, task=task)
  File "/home/airflow/.local/lib/python3.12/site-packages/airflow/models/taskinstance.py", line 1444, in _email_alert
    send_email(task.email, subject, html_content_err)
  File "/home/airflow/.local/lib/python3.12/site-packages/airflow/utils/email.py", line 80, in send_email
    return backend(
           ^^^^^^^^
  File "/home/airflow/.local/lib/python3.12/site-packages/airflow/utils/email.py", line 155, in send_email_smtp
    send_mime_email(e_from=mail_from, e_to=recipients, mime_msg=msg, conn_id=conn_id, dryrun=dryrun)
  File "/home/airflow/.local/lib/python3.12/site-packages/airflow/utils/email.py", line 274, in send_mime_email
    smtp_conn = _get_smtp_connection(smtp_host, smtp_port, smtp_timeout, smtp_ssl)
                ^^^^^^^^^^^^^^^^^^^^^^^^^^^^^^^^^^^^^^^^^^^^^^^^^^^^^^^^^^^^^^^^^^
  File "/home/airflow/.local/lib/python3.12/site-packages/airflow/utils/email.py", line 318, in _get_smtp_connection
    return smtplib.SMTP(host=host, port=port, timeout=timeout)
           ^^^^^^^^^^^^^^^^^^^^^^^^^^^^^^^^^^^^^^^^^^^^^^^^^^^
  File "/usr/local/lib/python3.12/smtplib.py", line 255, in __init__
    (code, msg) = self.connect(host, port)
                  ^^^^^^^^^^^^^^^^^^^^^^^^
  File "/usr/local/lib/python3.12/smtplib.py", line 341, in connect
    self.sock = self._get_socket(host, port, self.timeout)
                ^^^^^^^^^^^^^^^^^^^^^^^^^^^^^^^^^^^^^^^^^^
  File "/usr/local/lib/python3.12/smtplib.py", line 312, in _get_socket
    return socket.create_connection((host, port), timeout,
           ^^^^^^^^^^^^^^^^^^^^^^^^^^^^^^^^^^^^^^^^^^^^^^^
  File "/usr/local/lib/python3.12/socket.py", line 865, in create_connection
    raise exceptions[0]
  File "/usr/local/lib/python3.12/socket.py", line 850, in create_connection
    sock.connect(sa)
ConnectionRefusedError: [Errno 111] Connection refused
[2025-02-18T07:05:22.665+0000] {taskinstance.py:340} INFO - ::group::Post task execution logs
[2025-02-18T07:05:22.667+0000] {standard_task_runner.py:124} ERROR - Failed to execute job 99 for task insert_coin_data_postgres (duplicate key value violates unique constraint "coins_data_pkey"
DETAIL:  Key (id)=(1) already exists.
; 307)
Traceback (most recent call last):
  File "/home/airflow/.local/lib/python3.12/site-packages/airflow/task/task_runner/standard_task_runner.py", line 117, in _start_by_fork
    ret = args.func(args, dag=self.dag)
          ^^^^^^^^^^^^^^^^^^^^^^^^^^^^^
  File "/home/airflow/.local/lib/python3.12/site-packages/airflow/cli/cli_config.py", line 49, in command
    return func(*args, **kwargs)
           ^^^^^^^^^^^^^^^^^^^^^
  File "/home/airflow/.local/lib/python3.12/site-packages/airflow/utils/cli.py", line 116, in wrapper
    return f(*args, **kwargs)
           ^^^^^^^^^^^^^^^^^^
  File "/home/airflow/.local/lib/python3.12/site-packages/airflow/cli/commands/task_command.py", line 483, in task_run
    task_return_code = _run_task_by_selected_method(args, _dag, ti)
                       ^^^^^^^^^^^^^^^^^^^^^^^^^^^^^^^^^^^^^^^^^^^^
  File "/home/airflow/.local/lib/python3.12/site-packages/airflow/cli/commands/task_command.py", line 256, in _run_task_by_selected_method
    return _run_raw_task(args, ti)
           ^^^^^^^^^^^^^^^^^^^^^^^
  File "/home/airflow/.local/lib/python3.12/site-packages/airflow/cli/commands/task_command.py", line 341, in _run_raw_task
    return ti._run_raw_task(
           ^^^^^^^^^^^^^^^^^
  File "/home/airflow/.local/lib/python3.12/site-packages/airflow/utils/session.py", line 97, in wrapper
    return func(*args, session=session, **kwargs)
           ^^^^^^^^^^^^^^^^^^^^^^^^^^^^^^^^^^^^^^
  File "/home/airflow/.local/lib/python3.12/site-packages/airflow/models/taskinstance.py", line 3005, in _run_raw_task
    return _run_raw_task(
           ^^^^^^^^^^^^^^
  File "/home/airflow/.local/lib/python3.12/site-packages/airflow/models/taskinstance.py", line 273, in _run_raw_task
    TaskInstance._execute_task_with_callbacks(
  File "/home/airflow/.local/lib/python3.12/site-packages/airflow/models/taskinstance.py", line 3159, in _execute_task_with_callbacks
    result = self._execute_task(context, task_orig)
             ^^^^^^^^^^^^^^^^^^^^^^^^^^^^^^^^^^^^^^
  File "/home/airflow/.local/lib/python3.12/site-packages/airflow/models/taskinstance.py", line 3183, in _execute_task
    return _execute_task(self, context, task_orig)
           ^^^^^^^^^^^^^^^^^^^^^^^^^^^^^^^^^^^^^^^
  File "/home/airflow/.local/lib/python3.12/site-packages/airflow/models/taskinstance.py", line 767, in _execute_task
    result = _execute_callable(context=context, **execute_callable_kwargs)
             ^^^^^^^^^^^^^^^^^^^^^^^^^^^^^^^^^^^^^^^^^^^^^^^^^^^^^^^^^^^^^
  File "/home/airflow/.local/lib/python3.12/site-packages/airflow/models/taskinstance.py", line 733, in _execute_callable
    return ExecutionCallableRunner(
           ^^^^^^^^^^^^^^^^^^^^^^^^
  File "/home/airflow/.local/lib/python3.12/site-packages/airflow/utils/operator_helpers.py", line 252, in run
    return self.func(*args, **kwargs)
           ^^^^^^^^^^^^^^^^^^^^^^^^^^
  File "/home/airflow/.local/lib/python3.12/site-packages/airflow/models/baseoperator.py", line 422, in wrapper
    return func(self, *args, **kwargs)
           ^^^^^^^^^^^^^^^^^^^^^^^^^^^
  File "/home/airflow/.local/lib/python3.12/site-packages/airflow/operators/python.py", line 238, in execute
    return_value = self.execute_callable()
                   ^^^^^^^^^^^^^^^^^^^^^^^
  File "/home/airflow/.local/lib/python3.12/site-packages/airflow/operators/python.py", line 256, in execute_callable
    return runner.run(*self.op_args, **self.op_kwargs)
           ^^^^^^^^^^^^^^^^^^^^^^^^^^^^^^^^^^^^^^^^^^^
  File "/home/airflow/.local/lib/python3.12/site-packages/airflow/utils/operator_helpers.py", line 252, in run
    return self.func(*args, **kwargs)
           ^^^^^^^^^^^^^^^^^^^^^^^^^^
  File "/opt/airflow/dags/crypto_coins_dag.py", line 67, in insert_data_into_postgres
    postgres_hook.run(insert_query, parameters=(coin["id"], coin["Name"], coin["Symbol"], coin["Price"], coin["24h Percent Change"], coin["7d Percent Change"], coin["30d Percent Change"], coin["Market Cap"], coin["Circulating Supply"]))
  File "/home/airflow/.local/lib/python3.12/site-packages/airflow/providers/common/sql/hooks/sql.py", line 498, in run
    self._run_command(cur, sql_statement, parameters)
  File "/home/airflow/.local/lib/python3.12/site-packages/airflow/providers/common/sql/hooks/sql.py", line 556, in _run_command
    cur.execute(sql_statement, parameters)
psycopg2.errors.UniqueViolation: duplicate key value violates unique constraint "coins_data_pkey"
DETAIL:  Key (id)=(1) already exists.

[2025-02-18T07:05:22.683+0000] {local_task_job_runner.py:266} INFO - Task exited with return code 1
[2025-02-18T07:05:22.711+0000] {taskinstance.py:3895} INFO - 0 downstream tasks scheduled from follow-on schedule check
[2025-02-18T07:05:22.715+0000] {local_task_job_runner.py:245} INFO - ::endgroup::
